<?xml version="1.0" encoding="utf-8"?>
<!-- This URDF was automatically created by SolidWorks to URDF Exporter! Originally created by
Stephen Brawner (brawner@gmail.com) 
     Commit Version: 1.6.0-4-g7f85cfe  Build Version: 1.6.7995.38578
     For more information, please see http://wiki.ros.org/sw_urdf_exporter -->
<robot
  name="jamal_description">
  <link
    name="base">
    <inertial>
    <origin rpy="0 0 0" xyz="0.0 0 0.0"/>
      <mass value="12.8185384756311"/>
      <inertia ixx="0.0565667940678376" ixy="-8.54731557026013e-06" ixz="3.411601276539e-05" iyy="0.0364645326398335" iyz="-4.86965244292946e-06" izz="0.0737588756462406"/>
    </inertial>
    <visual>
      <origin
        xyz="0 0 0"
        rpy="0 0 0" />
      <geometry>
        <mesh
          filename="../dae/base.dae" />
      </geometry>
      <material
        name="">
        <color
          rgba="1 1 1 1" />
      </material>
    </visual>
    <collision>
      <origin rpy="0 0 0" xyz="0 0 0" />
      <geometry>
        <box size="0.3762 0.2 0.114" />
      </geometry>
    </collision>
  </link>
  <link
    name="FL_hip">
    <inertial>
      <origin rpy="0 0 0" xyz="0.0 0.0 0.0"/>
      <mass value="0.933762854916433"/>
      <inertia ixx="0.000832273911083319" ixy="2.01742652907359e-06" ixz="-9.96248193966734e-07" iyy="0.00106512043176046" iyz="-3.27660400510853e-06" izz="0.000803680416601427"/>
    </inertial>
    <visual>
      <origin
        xyz="0 0 0"
        rpy="0 0 0" />
      <geometry>
        <mesh
          filename="../dae/hip.dae" />
      </geometry>
      <material
        name="">
        <color
          rgba="1 1 1 1" />
      </material>
    </visual>
    <collision>
      <origin rpy="1.5707963267948966 0 0" xyz="0 0.0 0" />
      <geometry>
        <cylinder length="0.04" radius="0.046" />
      </geometry>
    </collision>
  </link>
  <joint
    name="FL_hip_joint"
    type="revolute">
    <origin
      rpy="0 0 0" xyz="0.2699 0.08028 0"/>
    <parent
      link="base" />
    <child
      link="FL_hip" />
    <axis
      xyz="1 0 0" />
    <limit
      lower="-0.53"
      upper="0.53"
      effort="100"
      velocity="8" />
  </joint>
  <link
    name="FL_thigh">
    <inertial>
      <origin rpy="0 0 0" xyz="0.0 0.0 0.0"/>
      <mass value="1.32134262348697"/>
      <inertia ixx="0.00262880898900224" ixy="3.0753036678596e-07" ixz="-6.6121911239445e-05" iyy="0.00316091750463634" iyz="4.01609105247509e-05" izz="0.00121962195056961"/>
    </inertial>
    <visual>
      <origin
        xyz="0 0 0"
        rpy="0 0 0" />
      <geometry>
        <mesh
          filename="../dae/thigh.dae" />
      </geometry>
      <material
        name="">
        <color
          rgba="1 1 1 1" />
      </material>
    </visual>
    <collision>
      <!-- <origin rpy="0 ${pi/2.0+0.1} 0" xyz="${thigh_x_offset} 0 ${-thigh_length/2.0}"/> -->
      <origin rpy="0 1.5707963267948966 0" xyz="0.0 0 -0.1125"/>
      <geometry>
        <box size="0.225 0.0245 0.034"/>
      </geometry>
    </collision>
    <collision>
      <origin rpy="1.5707963267948966 0 0" xyz="0 -0.008 0"/>
      <geometry>
        <cylinder length="0.032" radius="0.041"/>
      </geometry>
    </collision>
  </link>
  <joint
    name="FL_thigh_joint"
    type="revolute">
    <origin
      xyz="0 0.10755 0"
      rpy="0 0 0" />
    <parent
      link="FL_hip" />
    <child
      link="FL_thigh" />
    <axis
      xyz="0 1 0" />
    <limit
      lower="-1.5708"
      upper="3.4907"
      effort="100"
      velocity="8" />
  </joint>
  <link
    name="FL_calf">
    <inertial>
      <origin rpy="0 0 0" xyz="0.0 0.0 0.0"/>
      <mass value="0.12879265462489"/>
      <inertia ixx="0.000445341853265945" ixy="-7.71823686634482e-09" ixz="7.55836697902452e-05" iyy="0.000465686753688402" iyz="4.84096470394828e-09" izz="2.34278965180016e-05"/>
    </inertial>
    <visual>
      <origin
        xyz="0 0 0"
        rpy="0 0 0" />
      <geometry>
        <mesh
          filename="../dae/calf.dae" />
      </geometry>
      <material
        name="">
        <color
          rgba="1 1 1 1" />
      </material>
    </visual>
    <collision>
      <origin rpy="0 1.5707963267948966 0" xyz="0.0 0 -0.1175"/>
      <geometry>
        <box size="0.23 0.016 0.016"/>
      </geometry>
    </collision>
  </link>
  <joint
    name="FL_calf_joint"
    type="revolute">
    <origin
      xyz="0 0 -0.225"
      rpy="0 0 0" />
    <parent
      link="FL_thigh" />
    <child
      link="FL_calf" />
    <axis
      xyz="0 1 0" />
    <limit
      lower="-2.7227"
      upper="-0.83776"
      effort="100"
      velocity="20.07" />
  </joint>
  <link
    name="FL_foot">
    <inertial>
      <mass value="0.06"/>
      <inertia ixx="6.936000000000001e-06" ixy="0.0" ixz="0.0" iyy="6.936000000000001e-06" iyz="0.0" izz="6.936000000000001e-06"/>
    </inertial>
    <visual>
      <origin
        xyz="0 0 0"
        rpy="0 0 0" />
      <geometry>
        <mesh
          filename="../dae/foot.dae" />go2
      </geometry>
      <material
        name="">
        <color
          rgba="1 1 1 1" />
      </material>
    </visual>
    <collision>
      <origin rpy="0 0 0" xyz="0 0 0" />
      <geometry>
        <sphere radius="0.022" />
      </geometry>
    </collision>
  </link>
  <joint
    name="FL_foot_joint"
    type="fixed" dont_collapse="true">
    <origin
      xyz="0 0 -0.23"
      rpy="0 0 0" />
    <parent
      link="FL_calf" />
    <child
      link="FL_foot" />
    <axis
      xyz="0 0 0" />
  </joint>
  <link
    name="FR_hip">
    <inertial>
      <origin rpy="0 0 0" xyz="0.0 -0.0 0.0"/>
      <mass value="0.933762854916433"/>
      <inertia ixx="0.000832273911083319" ixy="-2.01742652907359e-06" ixz="-9.96248193966734e-07" iyy="0.00106512043176046" iyz="3.27660400510853e-06" izz="0.000803680416601427"/>
    </inertial>
    <visual>
      <origin
        xyz="0 0 0"
        rpy="3.1415 0 0" />
      <geometry>
        <mesh
          filename="../dae/hip.dae" />
      </geometry>
      <material
        name="">
        <color
          rgba="1 1 1 1" />
      </material>
    </visual>
    <collision>
      <origin rpy="1.5707963267948966 0 0" xyz="0 0 0"/>
      <geometry>
        <cylinder length="0.04" radius="0.046"/>
      </geometry>
    </collision>
  </link>
  <joint
    name="FR_hip_joint"
    type="revolute">
    <origin rpy="0 0 0" xyz="0.2699 -0.08028 0"/>
    <parent
      link="base" />
    <child
      link="FR_hip" />
    <axis
      xyz="1 0 0" />
    <limit
      lower="-0.53"
      upper="0.53"
      effort="100"
      velocity="8" />
  </joint>
  <link
    name="FR_thigh">
    <inertial>
      <origin rpy="0 0 0" xyz="0.0 -0.0 0.0"/>
      <mass value="1.32134262348697"/>
      <inertia ixx="0.00262880898900224" ixy="-3.0753036678596e-07" ixz="-6.6121911239445e-05" iyy="0.00316091750463634" iyz="-4.01609105247509e-05" izz="0.00121962195056961"/>
    </inertial>
    <visual>
      <origin
        xyz="0 0 0"
        rpy="0 0 0" />
      <geometry>
        <mesh
          filename="../dae/thigh_mirror.dae" />
      </geometry>
      <material
        name="">
        <color
          rgba="1 1 1 1" />
      </material>
    </visual>
    <collision>
      <!-- <origin rpy="0 ${pi/2.0+0.1} 0" xyz="${thigh_x_offset} 0 ${-thigh_length/2.0}"/> -->
      <origin rpy="0 1.5707963267948966 0" xyz="0.0 0 -0.1125"/>
      <geometry>
        <box size="0.225 0.0245 0.034"/>
      </geometry>
    </collision>
    <collision>
      <origin rpy="1.5707963267948966 0 0" xyz="0 0.008 0"/>
      <geometry>
        <cylinder length="0.032" radius="0.041"/>
      </geometry>
    </collision>
  </link>
  <joint
    name="FR_thigh_joint"
    type="revolute">
    <origin rpy="0 0 0" xyz="0 -0.10755 0"/>
    <parent
      link="FR_hip" />
    <child
      link="FR_thigh" />
    <axis
      xyz="0 1 0" />
    <limit
      lower="-1.5708"
      upper="3.4907"
      effort="100"
      velocity="8" />
  </joint>
  <link
    name="FR_calf">
    <inertial>
      <origin rpy="0 0 0" xyz="0.0 0.0 0.0"/>
      <mass value="0.12879265462489"/>
      <inertia ixx="0.000445341853265945" ixy="-7.71823686634482e-09" ixz="7.55836697902452e-05" iyy="0.000465686753688402" iyz="4.84096470394828e-09" izz="2.34278965180016e-05"/>
    </inertial>
    <visual>
      <origin
        xyz="0 0 0"
        rpy="0 0 0" />
      <geometry>
        <mesh
          filename="../dae/calf.dae" />
      </geometry>
      <material
        name="">
        <color
          rgba="1 1 1 1" />
      </material>
    </visual>
    <collision>
      <origin rpy="0 1.5707963267948966 0" xyz="0.0 0 -0.1175"/>
      <geometry>
        <box size="0.23 0.016 0.016"/>
      </geometry>
    </collision>
  </link>
  <joint
    name="FR_calf_joint"
    type="revolute">
    <origin rpy="0 0 0" xyz="0 0 -0.225"/>
    <parent
      link="FR_thigh" />
    <child
      link="FR_calf" />
    <axis
      xyz="0 1 0" />
    <limit
      lower="-2.7227"
      upper="-0.83776"
      effort="100"
      velocity="20.07" />
  </joint>
  <link
    name="FR_foot">
    <inertial>
      <mass value="0.06"/>
      <inertia ixx="6.936000000000001e-06" ixy="0.0" ixz="0.0" iyy="6.936000000000001e-06" iyz="0.0" izz="6.936000000000001e-06"/>
    </inertial>
    <visual>
      <origin
        xyz="0 0 0"
        rpy="0 0 0" />
      <geometry>
        <mesh
          filename="../dae/foot.dae" />
      </geometry>
      <material
        name="">
        <color
          rgba="1 1 1 1" />
      </material>
    </visual>
    <collision>
      <origin rpy="0 0 0" xyz="0 0 0"/>
      <geometry>
        <sphere radius="0.02"/>
      </geometry>
    </collision>
  </link>
  <joint
    name="FR_foot_joint"
    type="fixed" dont_collapse="true">
    <origin rpy="0 0 0" xyz="0 0 -0.23"/>
    <parent
      link="FR_calf" />
    <child
      link="FR_foot" />
    <axis
      xyz="0 0 0" />
  </joint>
  <link
    name="RL_hip">
    <inertial>
      <origin rpy="0 0 0" xyz="-0.0 0.0 0.0"/>
      <mass value="0.933762854916433"/>
      <inertia ixx="0.000832273911083319" ixy="-2.01742652907359e-06" ixz="9.96248193966734e-07" iyy="0.00106512043176046" iyz="-3.27660400510853e-06" izz="0.000803680416601427"/>
    </inertial>
    <visual>
      <origin
        xyz="0 0 0"
        rpy="0 3.1415 0" />
      <geometry>
        <mesh
          filename="../dae/hip.dae" />
      </geometry>
      <material
        name="">
        <color
          rgba="1 1 1 1" />
      </material>
    </visual>
    <collision>
      <origin rpy="1.5707963267948966 0 0" xyz="0 0 0"/>
      <geometry>
        <cylinder length="0.04" radius="0.046"/>
      </geometry>
    </collision>
  </link>
  <joint
    name="RL_hip_joint"
    type="revolute">
    <origin rpy="0 0 0" xyz="-0.2699 0.08028 0"/>
    <parent
      link="base" />
    <child
      link="RL_hip" />
    <axis
      xyz="1 0 0" />
    <limit
      lower="-0.53"
      upper="0.53"
      effort="100"
      velocity="8" />
  </joint>
  <link
    name="RL_thigh">
    <inertial>
      <origin rpy="0 0 0" xyz="0.0 0.0 0.0"/>
      <mass value="1.32134262348697"/>
      <inertia ixx="0.00262880898900224" ixy="3.0753036678596e-07" ixz="-6.6121911239445e-05" iyy="0.00316091750463634" iyz="4.01609105247509e-05" izz="0.00121962195056961"/>
    </inertial>
    <visual>
      <origin
        xyz="0 0 0"
        rpy="0 0 0" />
      <geometry>
        <mesh
          filename="../dae/thigh.dae" />
      </geometry>
      <material
        name="">
        <color
          rgba="1 1 1 1" />
      </material>
    </visual>
    <collision>
      <!-- <origin rpy="0 ${pi/2.0+0.1} 0" xyz="${thigh_x_offset} 0 ${-thigh_length/2.0}"/> -->
      <origin rpy="0 1.5707963267948966 0" xyz="0.0 0 -0.1125"/>
      <geometry>
        <box size="0.225 0.0245 0.034"/>
      </geometry>
    </collision>
    <collision>
      <origin rpy="1.5707963267948966 0 0" xyz="0 -0.008 0"/>
      <geometry>
        <cylinder length="0.032" radius="0.041"/>
      </geometry>
    </collision>
  </link>
  <joint
    name="RL_thigh_joint"
    type="revolute">
    <origin rpy="0 0 0" xyz="0 0.10755 0"/>
    <parent
      link="RL_hip" />
    <child
      link="RL_thigh" />
    <axis
      xyz="0 1 0" />
    <limit
      lower="-0.5236"
      upper="4.5379"
      effort="100"
      velocity="8" />
  </joint>
  <link
    name="RL_calf">
    <inertial>
      <origin rpy="0 0 0" xyz="0.0 0.0 0.0"/>
      <mass value="0.12879265462489"/>
      <inertia ixx="0.000445341853265945" ixy="-7.71823686634482e-09" ixz="7.55836697902452e-05" iyy="0.000465686753688402" iyz="4.84096470394828e-09" izz="2.34278965180016e-05"/>
    </inertial>
    <visual>
      <origin
        xyz="0 0 0"
        rpy="0 0 0" />
      <geometry>
        <mesh
          filename="../dae/calf.dae" />
      </geometry>
      <material
        name="">
        <color
          rgba="1 1 1 1" />
      </material>
    </visual>
    <collision>
      <origin rpy="0 1.5707963267948966 0" xyz="0.0 0 -0.1175"/>
      <geometry>
        <box size="0.23 0.016 0.016"/>
      </geometry>
    </collision>
  </link>
  <joint
    name="RL_calf_joint"
    type="revolute">
    <origin rpy="0 0 0" xyz="0 0 -0.225"/>
    <parent
      link="RL_thigh" />
    <child
      link="RL_calf" />
    <axis
      xyz="0 1 0" />
    <limit
      lower="-2.7227"
      upper="-0.83776"
      effort="100"
      velocity="20.07" />
  </joint>
  <link
    name="RL_foot">
    <inertial>
      <mass value="0.06"/>
      <inertia ixx="6.936000000000001e-06" ixy="0.0" ixz="0.0" iyy="6.936000000000001e-06" iyz="0.0" izz="6.936000000000001e-06"/>
    </inertial>
    <visual>
      <origin
        xyz="0 0 0"
        rpy="0 0 0" />
      <geometry>
        <mesh
          filename="../dae/foot.dae" />
      </geometry>
      <material
        name="">
        <color
          rgba="1 1 1 1" />
      </material>
    </visual>
    <collision>
      <origin rpy="0 0 0" xyz="0 0 0"/>
      <geometry>
        <sphere radius="0.02"/>
      </geometry>
    </collision>
  </link>
  <joint
    name="RL_foot_joint"
    type="fixed" dont_collapse="true">
    <origin rpy="0 0 0" xyz="0 0 -0.23"/>
    <parent
      link="RL_calf" />
    <child
      link="RL_foot" />
    <axis
      xyz="0 0 0" />
  </joint>
  <link
    name="RR_hip">
    <inertial>
      <origin rpy="0 0 0" xyz="-0.0 -0.0 0.0"/>
      <mass value="0.933762854916433"/>
      <inertia ixx="0.000832273911083319" ixy="2.01742652907359e-06" ixz="9.96248193966734e-07" iyy="0.00106512043176046" iyz="3.27660400510853e-06" izz="0.000803680416601427"/>
    </inertial>
    <visual>
      <origin
        xyz="0 0 0"
        rpy="3.1415 3.1415 0" />
      <geometry>
        <mesh
          filename="../dae/hip.dae" />
      </geometry>
      <material
        name="">
        <color
          rgba="1 1 1 1" />
      </material>
    </visual>
    <collision>
      <origin rpy="1.5707963267948966 0 0" xyz="0 0 0"/>
      <geometry>
        <cylinder length="0.04" radius="0.046"/>
      </geometry>
    </collision>
  </link>
  <joint
    name="RR_hip_joint"
    type="revolute">
    <origin rpy="0 0 0" xyz="-0.2699 -0.08028 0"/>
    <parent
      link="base" />
    <child
      link="RR_hip" />
    <axis
      xyz="1 0 0" />
    <limit
      lower="-0.53"
      upper="0.53"
      effort="100"
      velocity="8" />
  </joint>
  <link
    name="RR_thigh">
    <inertial>
      <origin rpy="0 0 0" xyz="0.0 -0.0 0.0"/>
      <mass value="1.32134262348697"/>
      <inertia ixx="0.00262880898900224" ixy="-3.0753036678596e-07" ixz="-6.6121911239445e-05" iyy="0.00316091750463634" iyz="-4.01609105247509e-05" izz="0.00121962195056961"/>
    </inertial>
    <visual>
      <origin
        xyz="0 0 0"
        rpy="0 0 0" />
      <geometry>
        <mesh
          filename="../dae/thigh_mirror.dae" />
      </geometry>
      <material
        name="">
        <color
          rgba="1 1 1 1" />
      </material>
    </visual>
    <collision>
      <!-- <origin rpy="0 ${pi/2.0+0.1} 0" xyz="${thigh_x_offset} 0 ${-thigh_length/2.0}"/> -->
      <origin rpy="0 1.5707963267948966 0" xyz="0.0 0 -0.1125"/>
      <geometry>
        <box size="0.225 0.0245 0.034"/>
      </geometry>
    </collision>
    <collision>
      <origin rpy="1.5707963267948966 0 0" xyz="0 0.008 0"/>
      <geometry>
        <cylinder length="0.032" radius="0.041"/>
      </geometry>
    </collision>
  </link>
  <joint
    name="RR_thigh_joint"
    type="revolute">
    <origin rpy="0 0 0" xyz="0 -0.10755 0"/>
    <parent
      link="RR_hip" />
    <child
      link="RR_thigh" />
    <axis
      xyz="0 1 0" />
    <limit
      lower="-0.5236"
      upper="4.5379"
      effort="100"
      velocity="8" />
  </joint>
  <link
    name="RR_calf">
    <inertial>
      <origin rpy="0 0 0" xyz="0.0 0.0 0.0"/>
      <mass value="0.12879265462489"/>
      <inertia ixx="0.000445341853265945" ixy="-7.71823686634482e-09" ixz="7.55836697902452e-05" iyy="0.000465686753688402" iyz="4.84096470394828e-09" izz="2.34278965180016e-05"/>
    </inertial>
    <visual>
      <origin
        xyz="0 0 0"
        rpy="0 0 0" />
      <geometry>
        <mesh
          filename="../dae/calf.dae" />
      </geometry>
      <material
        name="">
        <color
          rgba="1 1 1 1" />
      </material>
    </visual>
    <collision>
      <origin rpy="0 1.5707963267948966 0" xyz="0.0 0 -0.1175"/>
      <geometry>
        <box size="0.23 0.016 0.016"/>
      </geometry>
    </collision>
  </link>
  <joint
    name="RR_calf_joint"
    type="revolute">
    <origin rpy="0 0 0" xyz="0 0 -0.225"/>
    <parent
      link="RR_thigh" />
    <child
      link="RR_calf" />
    <axis
      xyz="0 1 0" />
    <limit
      lower="-2.7227"
      upper="-0.83776"
      effort="100"
      velocity="20.07" />
  </joint>
  <link
    name="RR_foot">
    <inertial>
      <mass value="0.06"/>
      <inertia ixx="6.936000000000001e-06" ixy="0.0" ixz="0.0" iyy="6.936000000000001e-06" iyz="0.0" izz="6.936000000000001e-06"/>
    </inertial>
    <visual>
      <origin
        xyz="0 0 0"
        rpy="0 0 0" />
      <geometry>
        <mesh
          filename="../dae/foot.dae" />
      </geometry>
      <material
        name="">
        <color
          rgba="1 1 1 1" />
      </material>
    </visual>
    <collision>
      <origin rpy="0 0 0" xyz="0 0 0"/>
      <geometry>
        <sphere radius="0.02"/>
      </geometry>
    </collision>
  </link>
  <joint
    name="RR_foot_joint"
    type="fixed" dont_collapse="true">
    <origin rpy="0 0 0" xyz="0 0 -0.23"/>
    <parent
      link="RR_calf" />
    <child
      link="RR_foot" />
    <axis
      xyz="0 0 0" />
  </joint>
  <link
    name="imu">
    <inertial>
      <origin
        xyz="0 0 0"
        rpy="0 0 0" />
      <mass
        value="0" />
      <inertia
        ixx="0"
        ixy="0"
        ixz="0"
        iyy="0"
        iyz="0"
        izz="0" />
    </inertial>
  </link>
  <joint
    name="imu_joint"
    type="fixed">
    <origin
      xyz="-0.02557 0 0.04232"
      rpy="0 0 0" />
    <parent
      link="base" />
    <child
      link="imu" />
    <axis
      xyz="0 0 0" />
  </joint>
</robot>