<?xml version="1.0" encoding="utf-8"?>
<!-- =================================================================================== -->
<!-- |    This document was autogenerated by xacro from /home/aeel/legged_control_ws/src/legged_control/legged_examples/legged_unitree/legged_unitree_description/urdf/robot.xacro | -->
<!-- |    EDITING THIS FILE BY HAND IS NOT RECOMMENDED                                 | -->
<!-- =================================================================================== -->
<robot name="jamal_description">
  <material name="black">
    <color rgba="0.0 0.0 0.0 1.0"/>
  </material>
  <material name="blue">
    <color rgba="0.0 0.0 0.8 1.0"/>
  </material>
  <material name="green">
    <color rgba="0.0 0.8 0.0 1.0"/>
  </material>
  <material name="grey">
    <color rgba="0.2 0.2 0.2 1.0"/>
  </material>
  <material name="silver">
    <color rgba="0.9137254901960784 0.9137254901960784 0.8470588235294118 1.0"/>
  </material>
  <material name="orange">
    <color rgba="1.0 0.4235294117647059 0.0392156862745098 1.0"/>
  </material>
  <material name="brown">
    <color rgba="0.8705882352941177 0.8117647058823529 0.7647058823529411 1.0"/>
  </material>
  <material name="red">
    <color rgba="0.8 0.0 0.0 1.0"/>
  </material>
  <material name="white">
    <color rgba="1.0 1.0 1.0 1.0"/>
  </material>
  <link name="base">
    <visual>
      <origin rpy="0 0 0" xyz="0 0 0"/>
      <geometry>
        <mesh filename="../dae/base.dae" scale="1 1 1"/>
      </geometry>
    </visual>
    <collision>
      <origin rpy="0 0 0" xyz="0 0 0"/>
      <geometry>
        <!-- <box size="0.3762 0.0935 0.114"/> -->
        <box size="0.3762 0.2 0.114"/>
      </geometry>
    </collision>
    <inertial>
      <!-- <origin rpy="0 0 0" xyz="0.03 0 0.0"/> -->
      <origin rpy="0 0 0" xyz="0.0 0 0.0"/>
      <mass value="12.8185384756311"/>
      <inertia ixx="0.0565667940678376" ixy="-8.54731557026013e-06" ixz="3.411601276539e-05" iyy="0.0364645326398335" iyz="-4.86965244292946e-06" izz="0.0737588756462406"/>
    </inertial>
  </link>
  <joint name="FL_hip_joint" type="revolute">
    <origin rpy="0 0 0" xyz="0.2699 0.08028 0"/>
    <parent link="base"/>
    <child link="LF_hip"/>
    <axis xyz="1 0 0"/>
    <!-- <dynamics damping="0.01" friction="0.2"/> -->
    <limit effort="100" lower="-0.863" upper="0.863" velocity="8"/>
  </joint>
  <link name="LF_hip">
    <visual>
      <origin rpy="0 0 0" xyz="0 0 0"/>
      <geometry>
        <mesh filename="../dae/hip.dae" scale="1 1 1"/>
      </geometry>
      <material name="orange"/>
    </visual>
    <collision>
      <origin rpy="1.5707963267948966 0 0" xyz="0 0 0"/>
      <geometry>
        <cylinder length="0.04" radius="0.046"/>
      </geometry>
    </collision>
    <inertial>
      <origin rpy="0 0 0" xyz="0.0 0.0 0.0"/>
      <mass value="0.933762854916433"/>
      <inertia ixx="0.000832273911083319" ixy="2.01742652907359e-06" ixz="-9.96248193966734e-07" iyy="0.00106512043176046" iyz="-3.27660400510853e-06" izz="0.000803680416601427"/>
    </inertial>
  </link>
  <joint name="FL_thigh_joint" type="revolute">
    <origin rpy="0 0 0" xyz="0 0.10755 0"/>
    <parent link="LF_hip"/>
    <child link="LF_thigh"/>
    <axis xyz="0 1 0"/>
    <!-- <dynamics damping="0.01" friction="0.2"/> -->
    <limit effort="100" lower="0.0" upper="1.57" velocity="8"/>
  </joint>
  <link name="LF_thigh">
    <visual>
      <origin rpy="0 0 0" xyz="0 0 0"/>
      <geometry>
        <mesh filename="../dae/thigh.dae" scale="1 1 1"/>
      </geometry>
      <material name="orange"/>
    </visual>
    <collision>
      <!-- <origin rpy="0 ${pi/2.0+0.1} 0" xyz="${thigh_x_offset} 0 ${-thigh_length/2.0}"/> -->
      <origin rpy="0 1.5707963267948966 0" xyz="0.0 0 -0.1125"/>
      <geometry>
        <box size="0.225 0.0245 0.034"/>
      </geometry>
    </collision>
    <collision>
      <origin rpy="1.5707963267948966 0 0" xyz="0 -0.008 0"/>
      <geometry>
        <cylinder length="0.032" radius="0.041"/>
      </geometry>
    </collision>
    <inertial>
      <origin rpy="0 0 0" xyz="0.0 0.0 0.0"/>
      <mass value="1.32134262348697"/>
      <inertia ixx="0.00262880898900224" ixy="3.0753036678596e-07" ixz="-6.6121911239445e-05" iyy="0.00316091750463634" iyz="4.01609105247509e-05" izz="0.00121962195056961"/>
    </inertial>
  </link>
  <joint name="FL_calf_joint" type="revolute">
    <origin rpy="0 0 0" xyz="0 0 -0.225"/>
    <parent link="LF_thigh"/>
    <child link="LF_calf"/>
    <axis xyz="0 1 0"/>
    <!-- <dynamics damping="0.01" friction="0.2"/> -->
    <limit effort="100" lower="-2.62" upper="-0.78" velocity="8"/>
  </joint>
  <link name="LF_calf">
    <visual>
      <!-- <origin rpy="0 0.06 0" xyz="0 0 0"/> -->
      <origin rpy="0 0 0" xyz="0 0 0"/>
      <geometry>
        <mesh filename="../dae/calf.dae" scale="1 1 1"/>
      </geometry>
      <material name="orange"/>
    </visual>
    <collision>
      <origin rpy="0 1.5707963267948966 0" xyz="0.0 0 -0.1175"/>
      <geometry>
        <box size="0.23 0.016 0.016"/>
      </geometry>
    </collision>
    <inertial>
      <origin rpy="0 0 0" xyz="0.0 0.0 0.0"/>
      <mass value="0.12879265462489"/>
      <inertia ixx="0.000445341853265945" ixy="-7.71823686634482e-09" ixz="7.55836697902452e-05" iyy="0.000465686753688402" iyz="4.84096470394828e-09" izz="2.34278965180016e-05"/>
    </inertial>
  </link>
  <joint dont_collapse="true" name="LF_foot_fixed" type="fixed">
    <origin rpy="0 0 0" xyz="0 0 -0.23"/>
    <parent link="LF_calf"/>
    <child link="LF_foot"/>
  </joint>
  <link name="LF_foot">
    <visual>
      <origin xyz="0 0 0" rpy="0 0 0"/>
      <geometry>
        <mesh filename="../dae/foot.dae"/>
      </geometry>
      <material name="orange"/>
    </visual>
    <collision>
      <origin rpy="0 0 0" xyz="0 0 0"/>
      <geometry>
        <sphere radius="0.02"/>
      </geometry>
    </collision>
    <inertial>
      <mass value="0.06"/>
      <inertia ixx="6.936000000000001e-06" ixy="0.0" ixz="0.0" iyy="6.936000000000001e-06" iyz="0.0" izz="6.936000000000001e-06"/>
    </inertial>
  </link>
  <joint name="RL_hip_joint" type="revolute">
    <origin rpy="0 0 0" xyz="-0.2699 0.08028 0"/>
    <parent link="base"/>
    <child link="LH_hip"/>
    <axis xyz="1 0 0"/>
    <!-- <dynamics damping="0.01" friction="0.2"/> -->
    <limit effort="100" lower="-0.863" upper="0.863" velocity="8"/>
  </joint>
  <link name="LH_hip">
    <visual>
      <origin rpy="0 3.141592653589793 0" xyz="0 0 0"/>
      <geometry>
        <mesh filename="../dae/hip.dae" scale="1 1 1"/>
      </geometry>
      <material name="orange"/>
    </visual>
    <collision>
      <origin rpy="1.5707963267948966 0 0" xyz="0 0 0"/>
      <geometry>
        <cylinder length="0.04" radius="0.046"/>
      </geometry>
    </collision>
    <inertial>
      <origin rpy="0 0 0" xyz="-0.0 0.0 0.0"/>
      <mass value="0.933762854916433"/>
      <inertia ixx="0.000832273911083319" ixy="-2.01742652907359e-06" ixz="9.96248193966734e-07" iyy="0.00106512043176046" iyz="-3.27660400510853e-06" izz="0.000803680416601427"/>
    </inertial>
  </link>
  <joint name="RL_thigh_joint" type="revolute">
    <origin rpy="0 0 0" xyz="0 0.10755 0"/>
    <parent link="LH_hip"/>
    <child link="LH_thigh"/>
    <axis xyz="0 1 0"/>
    <!-- <dynamics damping="0.01" friction="0.2"/> -->
    <limit effort="100" lower="-1.57" upper="0.0" velocity="8"/>
  </joint>
  <link name="LH_thigh">
    <visual>
      <origin rpy="0 0 0" xyz="0 0 0"/>
      <geometry>
        <mesh filename="../dae/thigh.dae" scale="1 1 1"/>
      </geometry>
      <material name="orange"/>
    </visual>
    <collision>
      <!-- <origin rpy="0 ${pi/2.0+0.1} 0" xyz="${thigh_x_offset} 0 ${-thigh_length/2.0}"/> -->
      <origin rpy="0 1.5707963267948966 0" xyz="0.0 0 -0.1125"/>
      <geometry>
        <box size="0.225 0.0245 0.034"/>
      </geometry>
    </collision>
    <collision>
      <origin rpy="1.5707963267948966 0 0" xyz="0 -0.008 0"/>
      <geometry>
        <cylinder length="0.032" radius="0.041"/>
      </geometry>
    </collision>
    <inertial>
      <origin rpy="0 0 0" xyz="0.0 0.0 0.0"/>
      <mass value="1.32134262348697"/>
      <inertia ixx="0.00262880898900224" ixy="3.0753036678596e-07" ixz="-6.6121911239445e-05" iyy="0.00316091750463634" iyz="4.01609105247509e-05" izz="0.00121962195056961"/>
    </inertial>
  </link>
  <joint name="RL_calf_joint" type="revolute">
    <origin rpy="0 0 0" xyz="0 0 -0.225"/>
    <parent link="LH_thigh"/>
    <child link="LH_calf"/>
    <axis xyz="0 1 0"/>
    <!-- <dynamics damping="0.01" friction="0.2"/> -->
    <limit effort="100" lower="0.78" upper="2.62" velocity="8"/>
  </joint>
  <link name="LH_calf">
    <visual>
      <!-- <origin rpy="0 0.06 0" xyz="0 0 0"/> -->
      <origin rpy="0 0 0" xyz="0 0 0"/>
      <geometry>
        <mesh filename="../dae/calf.dae" scale="1 1 1"/>
      </geometry>
      <material name="orange"/>
    </visual>
    <collision>
      <origin rpy="0 1.5707963267948966 0" xyz="0.0 0 -0.1175"/>
      <geometry>
        <box size="0.23 0.016 0.016"/>
      </geometry>
    </collision>
    <inertial>
      <origin rpy="0 0 0" xyz="0.0 0.0 0.0"/>
      <mass value="0.12879265462489"/>
      <inertia ixx="0.000445341853265945" ixy="-7.71823686634482e-09" ixz="7.55836697902452e-05" iyy="0.000465686753688402" iyz="4.84096470394828e-09" izz="2.34278965180016e-05"/>
    </inertial>
  </link>
  <joint dont_collapse="true" name="LH_foot_fixed" type="fixed">
    <origin rpy="0 0 0" xyz="0 0 -0.23"/>
    <parent link="LH_calf"/>
    <child link="LH_foot"/>
  </joint>
  <link name="LH_foot">
    <visual>
      <origin xyz="0 0 0" rpy="0 0 0"/>
      <geometry>
        <mesh filename="../dae/foot.dae"/>
      </geometry>
      <material name="orange"/>
    </visual>
    <collision>
      <origin rpy="0 0 0" xyz="0 0 0"/>
      <geometry>
        <sphere radius="0.02"/>
      </geometry>
    </collision>
    <inertial>
      <mass value="0.06"/>
      <inertia ixx="6.936000000000001e-06" ixy="0.0" ixz="0.0" iyy="6.936000000000001e-06" iyz="0.0" izz="6.936000000000001e-06"/>
    </inertial>
  </link>
  <joint name="FR_hip_joint" type="revolute">
    <origin rpy="0 0 0" xyz="0.2699 -0.08028 0"/>
    <parent link="base"/>
    <child link="RF_hip"/>
    <axis xyz="1 0 0"/>
    <!-- <dynamics damping="0.01" friction="0.2"/> -->
    <limit effort="100" lower="-0.863" upper="0.863" velocity="8"/>
  </joint>
  <link name="RF_hip">
    <visual>
      <origin rpy="3.141592653589793 0 0" xyz="0 0 0"/>
      <geometry>
        <mesh filename="../dae/hip.dae" scale="1 1 1"/>
      </geometry>
      <material name="orange"/>
    </visual>
    <collision>
      <origin rpy="1.5707963267948966 0 0" xyz="0 0 0"/>
      <geometry>
        <cylinder length="0.04" radius="0.046"/>
      </geometry>
    </collision>
    <inertial>
      <origin rpy="0 0 0" xyz="0.0 -0.0 0.0"/>
      <mass value="0.933762854916433"/>
      <inertia ixx="0.000832273911083319" ixy="-2.01742652907359e-06" ixz="-9.96248193966734e-07" iyy="0.00106512043176046" iyz="3.27660400510853e-06" izz="0.000803680416601427"/>
    </inertial>
  </link>
  <joint name="FR_thigh_joint" type="revolute">
    <origin rpy="0 0 0" xyz="0 -0.10755 0"/>
    <parent link="RF_hip"/>
    <child link="RF_thigh"/>
    <axis xyz="0 1 0"/>
    <!-- <dynamics damping="0.01" friction="0.2"/> -->
    <limit effort="100" lower="0.0" upper="1.57" velocity="8"/>
  </joint>
  <link name="RF_thigh">
    <visual>
      <origin rpy="0 0 0" xyz="0 0 0"/>
      <geometry>
        <mesh filename="../dae/thigh_mirror.dae" scale="1 1 1"/>
      </geometry>
      <material name="orange"/>
    </visual>
    <collision>
      <!-- <origin rpy="0 ${pi/2.0+0.1} 0" xyz="${thigh_x_offset} 0 ${-thigh_length/2.0}"/> -->
      <origin rpy="0 1.5707963267948966 0" xyz="0.0 0 -0.1125"/>
      <geometry>
        <box size="0.225 0.0245 0.034"/>
      </geometry>
    </collision>
    <collision>
      <origin rpy="1.5707963267948966 0 0" xyz="0 0.008 0"/>
      <geometry>
        <cylinder length="0.032" radius="0.041"/>
      </geometry>
    </collision>
    <inertial>
      <origin rpy="0 0 0" xyz="0.0 -0.0 0.0"/>
      <mass value="1.32134262348697"/>
      <inertia ixx="0.00262880898900224" ixy="-3.0753036678596e-07" ixz="-6.6121911239445e-05" iyy="0.00316091750463634" iyz="-4.01609105247509e-05" izz="0.00121962195056961"/>
    </inertial>
  </link>
  <joint name="FR_calf_joint" type="revolute">
    <origin rpy="0 0 0" xyz="0 0 -0.225"/>
    <parent link="RF_thigh"/>
    <child link="RF_calf"/>
    <axis xyz="0 1 0"/>
    <!-- <dynamics damping="0.01" friction="0.2"/> -->
    <limit effort="100" lower="-2.62" upper="-0.78" velocity="8"/>
  </joint>
  <link name="RF_calf">
    <visual>
      <!-- <origin rpy="0 0.06 0" xyz="0 0 0"/> -->
      <origin rpy="0 0 0" xyz="0 0 0"/>
      <geometry>
        <mesh filename="../dae/calf.dae" scale="1 1 1"/>
      </geometry>
      <material name="orange"/>
    </visual>
    <collision>
      <origin rpy="0 1.5707963267948966 0" xyz="0.0 0 -0.1175"/>
      <geometry>
        <box size="0.23 0.016 0.016"/>
      </geometry>
    </collision>
    <inertial>
      <origin rpy="0 0 0" xyz="0.0 0.0 0.0"/>
      <mass value="0.12879265462489"/>
      <inertia ixx="0.000445341853265945" ixy="-7.71823686634482e-09" ixz="7.55836697902452e-05" iyy="0.000465686753688402" iyz="4.84096470394828e-09" izz="2.34278965180016e-05"/>
    </inertial>
  </link>
  <joint dont_collapse="true" name="RF_foot_fixed" type="fixed">
    <origin rpy="0 0 0" xyz="0 0 -0.23"/>
    <parent link="RF_calf"/>
    <child link="RF_foot"/>
  </joint>
  <link name="RF_foot">
    <visual>
      <origin xyz="0 0 0" rpy="0 0 0"/>
      <geometry>
        <mesh filename="../dae/foot.dae"/>
      </geometry>
      <material name="orange"/>
    </visual>
    <collision>
      <origin rpy="0 0 0" xyz="0 0 0"/>
      <geometry>
        <sphere radius="0.02"/>
      </geometry>
    </collision>
    <inertial>
      <mass value="0.06"/>
      <inertia ixx="6.936000000000001e-06" ixy="0.0" ixz="0.0" iyy="6.936000000000001e-06" iyz="0.0" izz="6.936000000000001e-06"/>
    </inertial>
  </link>
  <joint name="RR_hip_joint" type="revolute">
    <origin rpy="0 0 0" xyz="-0.2699 -0.08028 0"/>
    <parent link="base"/>
    <child link="RH_hip"/>
    <axis xyz="1 0 0"/>
    <!-- <dynamics damping="0.01" friction="0.2"/> -->
    <limit effort="100" lower="-0.863" upper="0.863" velocity="8"/>
  </joint>
  <link name="RH_hip">
    <visual>
      <origin rpy="3.141592653589793 3.141592653589793 0" xyz="0 0 0"/>
      <geometry>
        <mesh filename="../dae/hip.dae" scale="1 1 1"/>
      </geometry>
      <material name="orange"/>
    </visual>
    <collision>
      <origin rpy="1.5707963267948966 0 0" xyz="0 0 0"/>
      <geometry>
        <cylinder length="0.04" radius="0.046"/>
      </geometry>
    </collision>
    <inertial>
      <origin rpy="0 0 0" xyz="-0.0 -0.0 0.0"/>
      <mass value="0.933762854916433"/>
      <inertia ixx="0.000832273911083319" ixy="2.01742652907359e-06" ixz="9.96248193966734e-07" iyy="0.00106512043176046" iyz="3.27660400510853e-06" izz="0.000803680416601427"/>
    </inertial>
  </link>
  <joint name="RR_thigh_joint" type="revolute">
    <origin rpy="0 0 0" xyz="0 -0.10755 0"/>
    <parent link="RH_hip"/>
    <child link="RH_thigh"/>
    <axis xyz="0 1 0"/>
    <!-- <dynamics damping="0.01" friction="0.2"/> -->
    <limit effort="100" lower="-1.57" upper="0.0" velocity="8"/>
  </joint>
  <link name="RH_thigh">
    <visual>
      <origin rpy="0 0 0" xyz="0 0 0"/>
      <geometry>
        <mesh filename="../dae/thigh_mirror.dae" scale="1 1 1"/>
      </geometry>
      <material name="orange"/>
    </visual>
    <collision>
      <!-- <origin rpy="0 ${pi/2.0+0.1} 0" xyz="${thigh_x_offset} 0 ${-thigh_length/2.0}"/> -->
      <origin rpy="0 1.5707963267948966 0" xyz="0.0 0 -0.1125"/>
      <geometry>
        <box size="0.225 0.0245 0.034"/>
      </geometry>
    </collision>
    <collision>
      <origin rpy="1.5707963267948966 0 0" xyz="0 0.008 0"/>
      <geometry>
        <cylinder length="0.032" radius="0.041"/>
      </geometry>
    </collision>
    <inertial>
      <origin rpy="0 0 0" xyz="0.0 -0.0 0.0"/>
      <mass value="1.32134262348697"/>
      <inertia ixx="0.00262880898900224" ixy="-3.0753036678596e-07" ixz="-6.6121911239445e-05" iyy="0.00316091750463634" iyz="-4.01609105247509e-05" izz="0.00121962195056961"/>
    </inertial>
  </link>
  <joint name="RR_calf_joint" type="revolute">
    <origin rpy="0 0 0" xyz="0 0 -0.225"/>
    <parent link="RH_thigh"/>
    <child link="RH_calf"/>
    <axis xyz="0 1 0"/>
    <!-- <dynamics damping="0.01" friction="0.2"/> -->
    <limit effort="100" lower="0.78" upper="2.62" velocity="8"/>
  </joint>
  <link name="RH_calf">
    <visual>
      <!-- <origin rpy="0 0.06 0" xyz="0 0 0"/> -->
      <origin rpy="0 0 0" xyz="0 0 0"/>
      <geometry>
        <mesh filename="../dae/calf.dae" scale="1 1 1"/>
      </geometry>
      <material name="orange"/>
    </visual>
    <collision>
      <origin rpy="0 1.5707963267948966 0" xyz="0.0 0 -0.1175"/>
      <geometry>
        <box size="0.23 0.016 0.016"/>
      </geometry>
    </collision>
    <inertial>
      <origin rpy="0 0 0" xyz="0.0 0.0 0.0"/>
      <mass value="0.12879265462489"/>
      <inertia ixx="0.000445341853265945" ixy="-7.71823686634482e-09" ixz="7.55836697902452e-05" iyy="0.000465686753688402" iyz="4.84096470394828e-09" izz="2.34278965180016e-05"/>
    </inertial>
  </link>
  <joint dont_collapse="true" name="RH_foot_fixed" type="fixed">
    <origin rpy="0 0 0" xyz="0 0 -0.23"/>
    <parent link="RH_calf"/>
    <child link="RH_foot"/>
  </joint>
  <link name="RH_foot">
    <visual>
      <origin xyz="0 0 0" rpy="0 0 0"/>
      <geometry>
        <mesh filename="../dae/foot.dae"/>
      </geometry>
      <material name="orange"/>
    </visual>
    <collision>
      <origin rpy="0 0 0" xyz="0 0 0"/>
      <geometry>
        <sphere radius="0.02"/>
      </geometry>
    </collision>
    <inertial>
      <mass value="0.06"/>
      <inertia ixx="6.936000000000001e-06" ixy="0.0" ixz="0.0" iyy="6.936000000000001e-06" iyz="0.0" izz="6.936000000000001e-06"/>
    </inertial>
  </link>
  <link
    name="imu">
    <inertial>
      <origin
        xyz="0 0 0"
        rpy="0 0 0" />
      <mass
        value="0" />
      <inertia
        ixx="0"
        ixy="0"
        ixz="0"
        iyy="0"
        iyz="0"
        izz="0" />
    </inertial>
  </link>
  <joint
    name="imu_joint"
    type="fixed">
    <origin
      xyz="-0.02557 0 0.04232"
      rpy="0 0 0" />
    <parent
      link="base" />
    <child
      link="imu" />
    <axis
      xyz="0 0 0" />
  </joint>
</robot>
